Workbook
Name AUD_Price: '[1]Product List'!$D$4:$D$36
Name CodeLookup: '[2]Current Rates'!$AA$2:$AB$12
Name Gross_Margin: #REF!
Name Gross_Margin: #REF!
Name List: #REF!
Name List: #REF!
Name NativeTimeline_Date: #N/A
Name NN: #REF!
Name Product_Name: '[1]Product List'!$B$4:$B$36
Name rateCodes: '[2]Current Rates'!$D$4:$D$13
Name Slicer_Country: #N/A
Name Slicer_Product: #N/A
Name Year: '[1]Sales Summary'!$A$4:$A$44

Sheet Data Entry
A1: Data entry rules
A3: One cell should represent only one entry
A5: Eg. | B5: Product Name | C5: Dosage Form | D5: Pack Type
B6: Naloxone | C6: Nasal Spray | D6: 2
B7: Diazepam | C7: Nasal Spray | D7: 2,6
A9: In Numerical entry, the data is always right aligned, it should be separated with commas and if it a currency then provide an appropriate symbol
B10: 2351279 | C10: 2351279 | E10: 2351279
A13: The Non-numeric data is always right alinged and it should always be in Title format ie the first word should be in Title format, and should be similar throughout the sheet
A15: Eg. | B15: Name | C15: Strength
B16: Paracetamol | C16: 100mg
B17: paracetamol | C17: 100 mg
B18: Ibuprofin | C18: 150Mg
B19: ibuprofin | C19: 150MG
B20: Ibuprofin | C20: 150 mg/mL
A22: The header for each column should be well speficied
A24: Eg. | B24: Product | C24: Sale | D24: Value
B25: Paracetamol | C25: 23000 | D25: 12000
B26: Ibuprofin | C26: 24569 | D26: 12500
A28: It is always preferable to enter the data in chronological order
A30: While refering the cell or any formula never hardcore the cell
A32: Never ever merge the cells. Only in rare cases where you have present data in ppt format or doc format

Sheet Shortcut Keys
A1: Select all | B1: Ctrl + A
A2: Select the whole column | B2: Ctrl + Space
A3: Select the whole row | B3: Shift + Space
A4: Select the whole range | B4: Ctrl + Shift + Space
A5: Select until last non-empty cell | B5: Ctrl + Shift + Arrow keys
A6: Go the end of the range | B6: Ctrl + Arrow keys
A7: Delete cells/rows/columns | B7: Ctrl + minus
A8: Add cells/rows/columns | B8: Shift+Control++
A9: Filter | B9: Shift +Control+L
A10: Find | B10: Ctrl + F
A11: Find and replace | B11: Ctrl + H
A12: Edit Cell | B12: F2
... A21: Formula to covert numerical data in millions | B21: [>=1000000] ###\,###\,##0;[>=100000] ###\,##0; ##,##0

Sheet Advanced_Filter
A1: Code | B1: Product Name | C1: Category | D1: Last Order | E1: Discontinued | I1: Category | J1: Last Order
A2: 2456 | B2: Oranges | C2: Fruit | D2: 41248 | E2: No | I2: Drinks | J2: >03-08-2012
A3: 3452 | B3: Tea | C3: Drinks | D3: 41186 | E3: No
A4: 4521 | B4: Kiwi juice | C4: Drinks | D4: 41124 | E4: Yes
A5: 2345 | B5: Olive oil | C5: Oil | D5: 41083 | E5: No
A6: 8735 | B6: Coffee | C6: Drinks | D6: 41213 | E6: No
A7: 6723 | B7: Dried Pears | C7: Fruit | D7: 41180 | E7: Yes
A8: 3452 | B8: Tea | C8: Drinks | D8: 41188 | E8: No
A9: 3451 | B9: Apples | C9: Fruit | D9: 41047 | E9: No
A10: 9801 | B10: Cottonseed | C10: Oil | D10: 40983 | E10: May be
A11: 3452 | B11: Tea | C11: Drinks | D11: 41186 | E11: No
A13: 2456 | B13: Oranges | C13: Fruit | D13: 41248 | E13: No
A14: 8735 | B14: Coffee | C14: Drinks | D14: 41213 | E14: No
A15: 3452 | B15: Tea | C15: Drinks | D15: 41188 | E15: No
... A17: 9801 | B17: Cottonseed | C17: Oil | D17: 40983 | E17: May be
A21: Code | B21: Product Name | C21: Category | D21: Last Order | E21: Discontinued
A22: 2456 | B22: Oranges | C22: Fruit | D22: 41248 | E22: No
A23: 3452 | B23: Tea | C23: Drinks | D23: 41186 | E23: No
A24: 4521 | B24: Kiwi juice | C24: Drinks | D24: 41124 | E24: Yes
A25: 2345 | B25: Olive oil | C25: Oil | D25: 41083 | E25: No
A26: 8735 | B26: Coffee | C26: Drinks | D26: 41213 | E26: No
A27: 6723 | B27: Dried Pears | C27: Fruit | D27: 41180 | E27: Yes
A28: 3452 | B28: Tea | C28: Drinks | D28: 41188 | E28: No
A29: 3451 | B29: Apples | C29: Fruit | D29: 41047 | E29: No
A30: 9801 | B30: Cottonseed | C30: Oil | D30: 40983 | E30: May be
A31: 3452 | B31: Tea | C31: Drinks | D31: 41186 | E31: No
I34: Category | J34: Discontinued
I35: Drinks
J36: Yes

Sheet Paste Special
A1: Paste special options
A3: 1. Copy and paste the following in cell F16 as transpose
C5: Jan | G5: Jan | H5: Feb | I5: Mar | J5: Apr
C6: Feb
C7: Mar
C8: Apr
A10: 2. Copy and paste the formatting of the below in cell F23
C12: Jan
C13: Feb
C14: Mar
C15: Apr
A17: 3. Copy the comment only and paste in cell F31
C19: Jan
C20: Feb
C21: Mar
C22: Apr
A24: 4. Copy the following and paste as link in cell E26
C26: Jan
C27: Feb
C28: Mar
C29: Apr
A31: 5. Use the multiply, add, subtract operations - How do they work?
C33: 3 | E33: 1
C34: 3 | E34: 2
C35: 4 | E35: 3
C36: 5 | E36: 2

Sheet Custome sort
A1: Custome sort the following data based on the chronological order
A3: Registration Date | B3: ID | F3: Day | G3: Sale per day
A4: 45394 | B4: 123 | F4: Mon | G4: 232
A5: 44949 | B5: 232 | F5: Tue | G5: 123
A6: 40685 | B6: 321 | F6: Thu | G6: 560
A7: 44774 | B7: 21 | F7: Thu | G7: 312
A8: 41185 | B8: 212 | F8: Fri | G8: 300

Sheet Freezing
A1: OrderID | B1: Item | C1: Year | D1: Month | E1: Region | F1: Rep | G1: Units | H1: ASP | I1: Sales (Rs) | J1: Cost (Rs)
A2: 44202 | B2: Pencil | C2: 2014 | D2: Jan | E2: East | F2: Jones | G2: 95 | H2: 1.99 | I2: 189.05 | J2: 11.343 | L2: 1. Freeze the header
A3: 44219 | B3: Binder | C3: 2014 | D3: Feb | E3: Central | F3: Kivell | G3: 50 | H3: 19.99 | I3: 999.5 | J3: 299.85 | L3: 2. Freeze header and the orderID column
A4: 44236 | B4: Pencil | C4: 2014 | D4: Mar | E4: Central | F4: Jardine | G4: 36 | H4: 4.99 | I4: 179.64 | J4: 64.6704 | L4: 3. Freeze header, orderID and item column
A5: 44253 | B5: Pen | C5: 2014 | D5: Apr | E5: Central | F5: Gill | G5: 27 | H5: 19.99 | I5: 539.73 | J5: 226.6866
A6: 44270 | B6: Pencil | C6: 2014 | D6: May | E6: West | F6: Sorvino | G6: 56 | H6: 2.99 | I6: 167.44 | J6: 75.348
A7: 44287 | B7: Binder | C7: 2014 | D7: Jun | E7: East | F7: Jones | G7: 60 | H7: 4.99 | I7: 299.4 | J7: 128.742
A8: 44304 | B8: Pencil | C8: 2014 | D8: Jul | E8: Central | F8: Andrews | G8: 75 | H8: 1.99 | I8: 149.25 | J8: 62.685
A9: 44321 | B9: Pencil | C9: 2014 | D9: Aug | E9: Central | F9: Jardine | G9: 90 | H9: 4.99 | I9: 449.1 | J9: 269.46
A10: 44338 | B10: Pencil | C10: 2014 | D10: Sep | E10: West | F10: Thompson | G10: 32 | H10: 1.99 | I10: 63.68 | J10: 10.8256
A11: 44355 | B11: Binder | C11: 2014 | D11: Oct | E11: East | F11: Jones | G11: 60 | H11: 8.99 | I11: 539.4 | J11: 231.942
A12: 44372 | B12: Pencil | C12: 2014 | D12: Nov | E12: Central | F12: Morgan | G12: 90 | H12: 4.99 | I12: 449.1 | J12: 157.185
A13: 44389 | B13: Binder | C13: 2014 | D13: Dec | E13: East | F13: Howard | G13: 29 | H13: 1.99 | I13: 57.71 | J13: 16.7359
A14: 44406 | B14: Binder | C14: 2015 | D14: Jan | E14: East | F14: Parent | G14: 81 | H14: 19.99 | I14: 1619.19 | J14: 841.9788
A15: 44423 | B15: Pencil | C15: 2015 | D15: Feb | E15: East | F15: Jones | G15: 35 | H15: 4.99 | I15: 174.65 | J15: 97.804
A16: 44440 | B16: Desk | C16: 2015 | D16: Mar | E16: Central | F16: Smith | G16: 2 | H16: 125 | I16: 250 | J16: 95
... A44: 44916 | B44: Binder | C44: 2014 | D44: Jul | E44: Central | F44: Andrews | G44: 28 | H44: 4.99 | I44: 139.72 | J44: 39.1216

Sheet Trim
A1: Remove the extra space in following name column
A3: ID | B3: Name | C3: Proper | D3: Trim
A4: 20167 | B4: Meena raut | C4: =PROPER(B4) -> Meena Raut | D4: =TRIM(C4) -> Meena Raut | E4: `
A5: 31982 | B5: Jay Naik | C5: =PROPER(B5) -> Jay Naik | D5: =TRIM(C5) -> Jay Naik | E5: =TRIM(PROPER(B5)) -> Jay Naik
A6: 21908 | B6: Satish Desai | C6: =PROPER(B6) -> Satish Desai | D6: =TRIM(C6) -> Satish Desai | E6: =TRIM(PROPER(B6)) -> Satish Desai
A7: 31269 | B7: Teena Pinto | C7: =PROPER(B7) -> Teena Pinto | D7: =TRIM(C7) -> Teena Pinto | E7: =TRIM(PROPER(B7)) -> Teena Pinto
A8: 45980 | B8: Odellia Ribello | C8: =PROPER(B8) -> Odellia Ribello | D8: =TRIM(C8) -> Odellia Ribello | E8: =TRIM(PROPER(B8)) -> Odellia Ribello
C11: ID | D11: 20167 | E11: 31982 | F11: 21908 | G11: 31269 | H11: 45980
C12: Name | D12: Meena raut | E12: Jay Naik | F12: Satish Desai | G12: Teena Pinto | H12: Odellia Ribello
C13: Proper | D13: =PROPER(D12) -> Meena Raut | E13: =PROPER(E12) -> Jay Naik | F13: =PROPER(F12) -> Satish Desai | G13: =PROPER(G12) -> Teena Pinto | H13: =PROPER(H12) -> Odellia Ribello
C14: Trim | D14: =TRIM(D13) -> Meena Raut | E14: =TRIM(E13) -> Jay Naik | F14: =TRIM(F13) -> Satish Desai | G14: =TRIM(G13) -> Teena Pinto | H14: =TRIM(H13) -> Odellia Ribello
D15: =TRIM(PROPER(D12)) -> Meena Raut | E15: =TRIM(PROPER(E12)) -> Jay Naik | F15: =TRIM(PROPER(F12)) -> Satish Desai | G15: =TRIM(PROPER(G12)) -> Teena Pinto | H15: =TRIM(PROPER(H12)) -> Odellia Ribello

Sheet Quick Navigation
A1: Quickly Navigate Larger Files
A3: Name box
A4: 1. Use the name box to jump to cell AB99 - What is in that cell?
A5: 2. Use the name box to jump to row200 column 200 - What is here?
A6: 3. Provide a name of your liking to cell A12 in this sheet. Go to the Index tab. Use the name box to jump to cell A12 in T3 (To the cell you just provided a name for).
A8: Color tab
A9: 1. Change the color of this tab to the color of your liking
A10: 2. Use the tab menu to navigate to "F3" tab
A12: Arrange worksheets
A13: You need to work with tab "T2" and "T3" simultaneously. Arrange them in the same window
AB99: Hi
GR200: Hello

Sheet Data formatting
A1: Sr No | B1: Product Name | C1: Strength | D1: Dosage form | E1: Pack type | F1: Site of manufacturing | G1: Filing Date | H1: Country | I1: Status | J1: Satge | K1: Year 1 Sale | L1: Year 2 Sale | M1: Year 3 sale | N1: Year 4 sale
A2: 1 | B2: Levofloxacin | C2: 5 ml | D2: Eye Drop | E2: bottle | F2: Canada. | G2: 44131 | H2: US | I2: Active | J2: 4 | K2: 3552880 | L2: 3601934 | M2: 5124873 | N2: 2117952
A3: 2 | B3: Dorzolamide + Timolol | C3: 10 ml | D3: Eye Drop | E3: bottle | F3: Ambernath | G3: 44131 | H3: US | I3: Active | J3: 5 | K3: 8325927 | L3: 7895295 | M3: 2192370 | N3: 1205448
A4: 3 | B4: Desvenlaflaxine ER | C4: 50mg | D4: Tablets | E4: Bottles | F4: Ambernath | G4: 44131 | H4: US | I4: Active | J4: 4 | K4: 9214741 | L4: 7136110 | M4: 2051125 | N4: 6827018
A5: 4 | B5: Desvenlaflaxine ER | C5: 100mg | D5: Tablet | E5: Bottle | F5: Ambernath | G5: 44131 | H5: Europe | I5: Active | J5: 5 | K5: 2597601 | L5: 7208778 | M5: 1455489 | N5: 7185260
A6: 5 | B6: Lamotrigine ER | C6: 25 mg | D6: Tablet | E6: Bottle | F6: Canada | G6: 44131 | H6: China | I6: Active | J6: 4 | K6: 6332111 | L6: 5644948 | M6: 9060794 | N6: 9183080
A7: 6 | B7: Lamotrigine ER | C7: 100 mg | D7: Tablet | E7: Bottles | F7: Ambernath | G7: 43696 | H7: US | I7: Active | J7: 5 | K7: 6621195 | L7: 5507650 | M7: 439008 | N7: 8976888
A8: 7 | B8: Lamotrigine ER | C8: 200 mg | D8: Tablet | E8: Bottle | F8: Ambernath | G8: 44740 | H8: US | I8: Active | J8: 4 | K8: 5703056 | L8: 3175729 | M8: 9526255 | N8: 69283
A9: 8 | B9: Buspirone HCl | C9: 5mg | D9: Tablet | E9: Bottle | F9: Ambernath | G9: 21st Jan 25 | H9: Germany | I9: Active | J9: 5 | K9: 5291782 | L9: 8160220 | M9: 6000560 | N9: 8411898
A10: 9 | B10: Buspirone HCl | C10: 10 mg | D10: Tablet | E10: bottle | F10: Ambernath | G10: 44740 | H10: US | I10: Active | J10: 3 | K10: 6576946 | L10: 8011858 | M10: 9540741 | N10: 3475710
A11: 10 | B11: Sildenafil Citrate | C11: 100mg | D11: Tablet | E11: Blister | F11: Ambernath | G11: 46932 | H11: US | I11: Active | J11: 1 | K11: 0 | L11: 0 | M11: 0 | N11: 0
A12: 11 | B12: sildenafil Citrate | C12: 100mg | D12: Tablet | E12: Blister | F12: Canada | G12: 44131 | H12: US | I12: Active | J12: 4 | K12: 9871138 | L12: 4966333 | M12: 9563695 | N12: 9503875
A13: 12 | B13: sildenafil Citrate | C13: 50mg | D13: Tablets | E13: Blister | F13: Ambernath | G13: 44131 | H13: US | I13: Active | J13: 5 | K13: 8556670 | L13: 463919 | M13: 5219177 | N13: 2679654
A14: 13 | B14: Sildenafil Citrate | C14: 50mg | D14: Tablet | E14: Blister | F14: Ambernath | G14: 44131 | H14: US | I14: Active | J14: 4 | K14: 1870409 | L14: 5939395 | M14: 8468632 | N14: 5825991
A15: 14 | B15: Rabeprazole Sodium DR | C15: 20 mg | D15: Tablet | E15: Bottle | F15: Canada | G15: 44131 | H15: Germany | I15: Active | J15: 5 | K15: 5157248 | L15: 3504283 | M15: 7960332 | N15: 8875451
A16: 15 | B16: Diclofenac Potassium | C16: 50mg | D16: Tablet | E16: Bottle | F16: Ambernath | G16: 46687 | H16: Canada | I16: Active | J16: 1
A17: 16 | B17: Pantoprazol | C17: 20 mg | D17: Tablet | E17: Bottle | F17: Ambernath | G17: 44131 | H17: Canada | I17: Active | J17: 4 | K17: 2572201 | L17: 7927421 | M17: 398718 | N17: 4738825
A18: 17 | B18: Pantoprazol | C18: 40 mg | D18: Tablet | E18: Bottle | F18: Ambernath | G18: 44131 | H18: Canada | I18: Active | J18: 5 | K18: 6044115 | L18: 5923239 | M18: 2542618 | N18: 5638565
A19: 18 | B19: Lamotrigine IR | C19: 100mg | D19: Tablet | E19: Bottle | F19: Ambernath | G19: 44131 | H19: Canada | I19: Active | J19: 4 | K19: 4733191 | L19: 5742703 | M19: 7639842 | N19: 379507
A20: 19 | B20: Lamotrigine IR | C20: 200 mg | D20: Tablet | E20: Bottle | F20: Ambernath | G20: 45100 | H20: US | I20: Active | J20: 5 | K20: 9596607 | L20: 8415127 | M20: 1842911 | N20: 6697745
A21: 20 | B21: Metolazone | C21: 2.5 mg | D21: Tablet | E21: Bottle | F21: Ambernath | G21: 47354 | H21: US | I21: Active | J21: 4 | K21: 9594351 | L21: 8486823 | M21: 9622595 | N21: 5246735
A22: 21 | B22: Metolazone | C22: 5 mg | D22: Tablet | E22: Bottle | F22: Ambernath | G22: 45881 | H22: US | I22: Active | J22: 4 | K22: 7016187 | L22: 3190663 | M22: 1816700 | N22: 9315215
A23: 22 | B23: Nitroglycerine | C23: 0.3 mg | D23: Tablet | E23: Bottles | F23: Ambernath | G23: 44825 | H23: US | I23: Active | J23: 5 | K23: 9139289 | L23: 7196632 | M23: 7182546 | N23: 582009
A24: 23 | B24: Nitroglycerine | C24: 0.4 mg | D24: Tablet | E24: Bottles | F24: Ambernath | G24: 44825 | H24: US | I24: Active | J24: 4 | K24: 9070553 | L24: 1424660 | M24: 3475906 | N24: 4877859
A25: 24 | B25: Nitroglycerine | C25: 0.6 mg | D25: Tablet | E25: Bottles | F25: Canada | G25: 44825 | H25: Europe | I25: Active | J25: 5 | K25: 9273217 | L25: 9616033 | M25: 2761923 | N25: 8667644
A26: 25 | B26: Potassium Chloride | C26: 20MEQ/15mg | D26: Solution | E26: Bottles | F26: Canada | G26: 36805 | H26: US | I26: Active | J26: 4 | K26: 4429953 | L26: 7789239 | M26: 9158864 | N26: 4074846
A27: 26 | B27: Potassium Cl | C27: 40MEQ/15mg | D27: Solution | E27: Bottle | F27: Ambernath | G27: 36805 | H27: Nordic | I27: Active | J27: 1
A28: 27 | B28: Labetalol Hydrochloride | C28: 200 mg | D28: Tablet | E28: Bottle | F28: Ambernath | G28: 36805 | H28: Nordic | I28: Active | J28: 1
A29: 28 | B29: Labetalol HCl | C29: 100 mg | F29: Ambernath | G29: 44426 | H29: Nordic | I29: Active | J29: 5 | K29: 1910259 | L29: 7381435 | M29: 9278507 | N29: 2817689
A30: 29 | B30: Potassium Chloride | C30: 20MEQ/15mg | D30: Solution | E30: Bottle | F30: Ambernath | G30: 44426 | H30: Nordic | I30: Active | J30: 4 | K30: 3773964 | L30: 6419065 | M30: 8431588 | N30: 2442326
A31: 30 | B31: Potassium Chloride | C31: 40MEQ/15mg | D31: Solution | E31: Bottle | F31: Canada | G31: 44426 | H31: US | I31: Active | J31: 5 | K31: 7265864 | L31: 6205995 | M31: 9407907 | N31: 491415
A32: 31 | B32: Amiodarone HCl | C32: 200 mg | D32: Tablet | E32: Blister | F32: Ambernath | G32: 44428 | H32: MEA | I32: Active | J32: 4 | K32: 410095 | L32: 4521677 | M32: 432405 | N32: 1339909
A33: 32 | B33: Desvenlaflaxine ER | C33: 50 mg | D33: Tablet | E33: Blisters | F33: Ambernath | G33: 44428 | H33: MEA | I33: Active | J33: 5 | K33: 4408770 | L33: 9601407 | M33: 2175653 | N33: 7057290
A34: 33 | B34: Desvenlaflaxine ER | C34: 100 mg | D34: Tablet | E34: Blisters | F34: Ambernath | G34: 44428 | H34: MEA | I34: Active | J34: 4 | K34: 2054548 | L34: 4041108 | M34: 5494229 | N34: 2280876
A35: 34 | B35: Metoprolol Tartrate | C35: 50 mg | D35: Tablet | E35: Blister | F35: Ambernath | G35: 41940 | H35: MEA | I35: Active | J35: 5 | K35: 31343 | L35: 443402 | M35: 7863497 | N35: 9350284
A36: 35 | B36: Metoprolol Tartrate | C36: 100 mg | D36: Tablet | E36: Blister | F36: Ambernath | G36: 43698 | H36: US | I36: Active | J36: 4 | K36: 7004726 | L36: 1569173 | M36: 5862204 | N36: 4397940
A37: 36 | B37: Pantoprazol | C37: 40 mg | D37: tablet | E37: Blister | F37: Ambernath | G37: 21st Oct 25 | H37: US | I37: Active | J37: 1
A38: 37 | B38: Rabeprazole Sodium | C38: 20 mg | D38: Tablet | E38: Blister | F38: Ambernath | G38: 43698 | H38: UK | I38: Active | J38: 5 | K38: 975613 | L38: 1984053 | M38: 7724370 | N38: 1779984
A39: 38 | B39: Loratadine | C39: 10 mg | D39: Tablet | E39: Blister | F39: Ambernath | G39: 41940 | H39: UK | I39: Active | J39: 4 | K39: 5325856 | L39: 3566965 | M39: 9863577 | N39: 8819083
A40: 39 | B40: Fluoxetine Hydrochloride | C40: 20 mg/5 ml | D40: Solution | E40: bottle | F40: Ambernath | G40: 43696 | H40: UK | I40: Active | J40: 4 | K40: 2079959 | L40: 9152406 | M40: 1581792 | N40: 9845113
...

Sheet Data cleaning
A1: Sr No | B1: Product Name | D1: Strength | E1: Dosage form | F1: Pack type | G1: Site of manufacturing | H1: Filing Date | I1: Country | J1: Status | K1: Satge | L1: Year 1 Sale | M1: Year 2 Sale | N1: Year 3 sale | O1: Year 4 sale
A2: 1 | B2: Levofloxacin | D2: 5 ml | E2: Eye Drop | F2: Bottle | G2: Canada. | H2: 44770 | I2: US | J2: Active | K2: 4 | L2: 3552880 | M2: 3601934 | N2: 5124873 | O2: 2117952
A3: 2 | B3: Dorzolamide + Timolol | D3: 10 ml | E3: Eye Drop | F3: Bottle | G3: Ambernath | H3: 44740 | I3: US | J3: Active | K3: 5 | L3: 8325927 | M3: 7895295 | N3: 2192370 | O3: 1205448
A4: 3 | B4: Desvenlaflaxine ER | D4: 50 mg | E4: Tablets | F4: Bottles | G4: Ambernath | H4: 44740 | I4: US | J4: Active | K4: 4 | L4: 9214741 | M4: 7136110 | N4: 2051125 | O4: 6827018
A5: 4 | B5: Desvenlaflaxine ER | D5: 100MG | E5: Tablet | F5: Bottle | G5: Ambernath | H5: 44740 | I5: Europe | J5: Active | K5: 5 | L5: 2597601 | M5: 7208778 | N5: 1455489 | O5: 7185260
A6: 5 | B6: Lamotrigine ER | D6: 25 mg | E6: Tablet | F6: Bottle | G6: Canada | H6: 44740 | I6: China | J6: Active | K6: 4 | L6: 6332111 | M6: 5644948 | N6: 9060794 | O6: 9183080
A7: 6 | B7: Lamotrigine ER | D7: 100 mg | E7: Tablet | F7: Bottles | G7: Ambernath | H7: 43696 | I7: US | J7: Active | K7: 5 | L7: 6621195 | M7: 5507650 | N7: 439008 | O7: 8976888
A8: 7 | B8: Lamotrigine ER | D8: 200 mg | E8: tablet | F8: Bottle | G8: Ambernath | H8: 44740 | I8: US | J8: Active | K8: 4 | L8: 5703056 | M8: 3175729 | N8: 9526255 | O8: 69283
A9: 8 | B9: Buspirone HCl | D9: 5mg | E9: Tablet | F9: Bottle | G9: Ambernath | H9: 21st Jan 25 | I9: Germany | J9: Active | K9: 5 | L9: 5291782 | M9: 8160220 | N9: 6000560 | O9: 8411898
A10: 9 | B10: Buspirone HCl | D10: 10 mg | E10: Tablet | F10: Bottle | G10: Ambernath | H10: 44740 | I10: USA | J10: Active | K10: 3 | L10: 6576946 | M10: 8011858 | N10: 9540741 | O10: 3475710
A11: 10 | B11: Sildenafil Citrate | D11: 100mg | E11: Tablet | F11: Blister | G11: Ambernath | H11: 46932 | I11: US | J11: Active | K11: 1 | L11: 0 | M11: 0 | N11: 0 | O11: 0
A12: 11 | B12: sildenafil Citrate | D12: 100mg | E12: Tablet | F12: Blister | G12: Canada | H12: 45980 | I12: US | J12: Active | K12: 4 | L12: 9871138 | M12: 4966333 | N12: 9563695 | O12: 9503875
A13: 12 | B13: sildenafil Citrate | D13: 50mg | E13: Tablets | F13: Blister | G13: Ambernath | H13: 44131 | I13: US | J13: Active | K13: 5 | L13: 8556670 | M13: 463919 | N13: 5219177 | O13: 2679654
A14: 13 | B14: Sildenafil Citrate | D14: 50mg | E14: Tablet | F14: Blister | G14: Ambernath | H14: 45980 | I14: USA | J14: Active | K14: 4 | L14: 1870409 | M14: 5939395 | N14: 8468632 | O14: 5825991
A15: 14 | B15: Rabeprazole Sodium DR | D15: 20 mg | E15: Tablet | F15: Bottle | G15: Canada | H15: 44884 | I15: Germany | J15: Active | K15: 5 | L15: 5157248 | M15: 3504283 | N15: 7960332 | O15: 8875451
A16: 15 | B16: Diclofenac Potassium | D16: 50mg | E16: Tablet | F16: Bottle | G16: Ambernath | H16: 45980 | I16: Canada | J16: Active | K16: 1 | M16: 0
A17: 16 | B17: Pantoprazol | D17: 20 mg | E17: Tablet | F17: L | G17: Ambernath | H17: 43818 | I17: Canada | J17: Active | K17: 4 | L17: 2572201 | M17: 7927421 | N17: 398718 | O17: 4738825
A18: 17 | B18: Pantoprazol | D18: 40 mg | E18: Tablet | F18: Bottle | G18: Ambernath | H18: 39101 | I18: Canada | J18: Active | K18: 5 | L18: 6044115 | M18: 5923239 | N18: 2542618 | O18: 5638565
A19: 18 | B19: Lamotrigine IR | D19: 100 mg | E19: Tablet | F19: Bottle | G19: Ambernath | H19: 38371 | I19: Canada | J19: Active | K19: 4 | L19: 4733191 | M19: 5742703 | N19: 7639842 | O19: 379507
A20: 19 | B20: Lamotrigine IR | D20: 200 mg | E20: Tablet | F20: Bottle | G20: Ambernath | H20: 41940 | I20: US | J20: Active | K20: 5 | L20: 9596607 | M20: 8415127 | N20: 1842911 | O20: 6697745
A21: 20 | B21: Dorzolamide + Timolol | D21: 2.5 mg | E21: Eye Drops | F21: Bottle | G21: Ambernath | H21: 41940 | I21: US | J21: Active | K21: 4 | L21: 9594351 | M21: 8486823 | N21: 9622595 | O21: 5246735
A22: 21 | B22: Metolazone | D22: 5 mg | E22: Tablet | F22: Bottle | G22: Ambernath | H22: 41940 | I22: US | J22: Active | K22: 4 | L22: 7016187 | M22: 3190663 | N22: 1816700 | O22: 9315215
A23: 22 | B23: Nitroglycerine | D23: 0.3 mg | E23: Tablet | F23: Bottles | G23: Ambernath | H23: 44825 | I23: US | J23: Active | K23: 5 | L23: 9139289 | M23: 7196632 | N23: 7182546 | O23: 582009
A24: 23 | B24: Nitroglycerine | D24: 0.4 mg | E24: Tablet | F24: Bottles | G24: Ambernath | H24: 44825 | I24: US | J24: Active | K24: 4 | L24: 9070553 | M24: 1424660 | N24: 3475906 | O24: 4877859
A25: 24 | B25: Nitroglycerine | D25: 0.6 mg | E25: Tablet | F25: Bottles | G25: Canada | H25: 44825 | I25: Europe | J25: Active | K25: 5 | L25: 9273217 | M25: 9616033 | N25: 2761923 | O25: 8667644
A26: 25 | B26: Potassium Chloride | D26: 20MEQ/15mg | E26: Solution | F26: Bottles | G26: Canada | H26: 36805 | I26: US | J26: Active | K26: 4 | L26: 4429953 | M26: 7789239 | N26: 9158864 | O26: 4074846
A27: 26 | B27: Potassium Cl | D27: 40MEQ/15mg | E27: Solution | F27: Bottle | G27: Ambernath | H27: 36805 | I27: Nordic | J27: Active | K27: 1 | L27: 0
A28: 27 | B28: Labetalol Hydrochloride | D28: 200 mg | E28: Tablet | F28: Bottle | G28: Ambernath | H28: 36805 | I28: Nordic | J28: Active | K28: 1 | L28: 0
A29: 28 | B29: Labetalol HCl | D29: 100 mg | G29: Ambernath | H29: 44426 | I29: Nordic | J29: Active | K29: 5 | L29: 1910259 | M29: 7381435 | N29: 9278507 | O29: 2817689
A30: 29 | B30: Potassium Chloride | D30: 20MEQ/15mg | E30: Solution | F30: Bottle | G30: Ambernath | H30: 44426 | I30: Nordic | J30: Active | K30: 4 | L30: 3773964 | M30: 6419065 | N30: 8431588 | O30: 2442326
A31: 30 | B31: Potassium Chloride | D31: 40MEQ/15mg | E31: Solution | F31: Bottle | G31: Canada | H31: 44426 | I31: USA | J31: Active | K31: 5 | L31: 7265864 | M31: 6205995 | N31: 9407907 | O31: 491415
A32: 31 | B32: Amiodarone HCl | D32: 200 mg | E32: Tablet | F32: Blister | G32: Ambernath | H32: 44428 | I32: MEA | J32: Active | K32: 4 | L32: 410095 | M32: 4521677 | N32: 432405 | O32: 1339909
A33: 32 | B33: Desvenlaflaxine ER | D33: 50 mg | E33: Tablet | F33: Blisters | G33: Ambernath | H33: 44428 | I33: MEA | J33: Active | K33: 5 | L33: 4408770 | M33: 9601407 | N33: 2175653 | O33: 7057290
A34: 33 | B34: Desvenlaflaxine ER | D34: 100 mg | E34: Tablet | F34: Blisters | G34: Ambernath | H34: 44428 | I34: MEA | J34: Active | K34: 4 | L34: 2054548 | M34: 4041108 | N34: 5494229 | O34: 2280876
A35: 34 | B35: Metoprolol Tartrate | D35: 50 mg | E35: Tablet | F35: Blister | G35: Ambernath | H35: 41940 | I35: MEA | J35: Active | K35: 5 | L35: 31343 | M35: 443402 | N35: 7863497 | O35: 9350284
A36: 35 | B36: Metoprolol Tartrate | D36: 100 mg | E36: Tablet | F36: Blister | G36: Ambernath | H36: 43698 | I36: US | J36: Active | K36: 4 | L36: 7004726 | M36: 1569173 | N36: 5862204 | O36: 4397940
A37: 36 | B37: Pantoprazol | D37: 40 mg | E37: tablet | F37: Blister | G37: Ambernath | H37: 21st Oct 25 | I37: US | J37: Active | K37: 1
A38: 37 | B38: Rabeprazole Sodium | D38: 20 mg | E38: Tablet | F38: Blister | G38: Ambernath | H38: 43698 | I38: UK | J38: Active | K38: 5 | L38: 975613 | M38: 1984053 | N38: 7724370 | O38: 1779984
A39: 38 | B39: Loratadine | D39: 10 mg | E39: Tablet | F39: Blister | G39: Ambernath | H39: 41940 | I39: UK | J39: Active | K39: 4 | L39: 5325856 | M39: 3566965 | N39: 9863577 | O39: 8819083
A40: 39 | B40: Fluoxetine Hydrochloride | D40: 20 mg/5 ml | E40: Solution | F40: Bottle | G40: Ambernath | H40: 43696 | I40: UK | J40: Active | K40: 4 | L40: 2079959 | M40: 9152406 | N40: 1581792 | O40: 9845113
...

Sheet Count
A1: Count Function
B3: Code | C3: Product Name | D3: Category | E3: Last Order | F3: Discontinued | G3: Countif | H3: Countifs | L3: Last Order
B4: 2456 | C4: Oranges | D4: Fruit | E4: 41248 | F4: No | G4: =COUNTIF($D$4:$D$12,D4) -> 3 | H4: =COUNTIFS($D$4:$D$12,D4,$F$4:$F$12,F4) -> 2 | I4: =COUNTIF($C$4:$C$12,C6) -> 1 | J4: =COUNTIFS($C$4:$C$12,C4,$D$4:$D$12,D4) -> 2
B5: 3452 | C5: Tea | D5: Drinks | E5: 41186 | F5: No | G5: =COUNTIF($D$4:$D$12,D5) -> 4 | H5: =COUNTIFS($D$4:$D$12,D5,$F$4:$F$12,F5) -> 2 | I5: =COUNTIF($C$4:$C$12,C7) -> 1 | J5: =COUNTIFS($C$4:$C$12,C5,$D$4:$D$12,D5) -> 3
B6: 4521 | C6: Kiwi juice | D6: Drinks | E6: 41124 | F6: Yes | G6: =COUNTIF($D$4:$D$12,D6) -> 4 | H6: =COUNTIFS($D$4:$D$12,D6,$F$4:$F$12,F6) -> 1 | I6: =COUNTIF($C$4:$C$12,C8) -> 3 | J6: =COUNTIFS($C$4:$C$12,C6,$D$4:$D$12,D6) -> 1
B7: 2345 | C7: Olive oil | D7: Oil | E7: 41083 | F7: No | G7: =COUNTIF($D$4:$D$12,D7) -> 2 | H7: =COUNTIFS($D$4:$D$12,D7,$F$4:$F$12,F7) -> 1 | I7: =COUNTIF($C$4:$C$12,C9) -> 2 | J7: =COUNTIFS($C$4:$C$12,C7,$D$4:$D$12,D7) -> 1
B8: 8735 | C8: Tea | D8: Drinks | E8: 41213 | F8: No | G8: =COUNTIF($D$4:$D$12,D8) -> 4 | H8: =COUNTIFS($D$4:$D$12,D8,$F$4:$F$12,F8) -> 2 | I8: =COUNTIF($C$4:$C$12,C10) -> 3 | J8: =COUNTIFS($C$4:$C$12,C8,$D$4:$D$12,D8) -> 3
B9: 6723 | C9: oranges | D9: Fruit | E9: 41180 | F9: Yes | G9: =COUNTIF($D$4:$D$12,D9) -> 3 | H9: =COUNTIFS($D$4:$D$12,D9,$F$4:$F$12,F9) -> 1 | I9: =COUNTIF($C$4:$C$12,C11) -> 1 | J9: =COUNTIFS($C$4:$C$12,C9,$D$4:$D$12,D9) -> 2
B10: 3452 | C10: Tea | D10: Drinks | E10: 41188 | G10: =COUNTIF($D$4:$D$12,D10) -> 4 | H10: =COUNTIFS($D$4:$D$12,D10,$F$4:$F$12,F10) -> 0 | I10: =COUNTIF($C$4:$C$12,C12) -> 1 | J10: =COUNTIFS($C$4:$C$12,C10,$D$4:$D$12,D10) -> 3
B11: 3451 | C11: Apples | D11: Fruit | E11: 41047 | F11: No | G11: =COUNTIF($D$4:$D$12,D11) -> 3 | H11: =COUNTIFS($D$4:$D$12,D11,$F$4:$F$12,F11) -> 2 | I11: =COUNTIF($C$4:$C$12,C13) -> 0 | J11: =COUNTIFS($C$4:$C$12,C11,$D$4:$D$12,D11) -> 1
B12: 9801 | C12: Cottonseed | D12: Oil | E12: 40983 | F12: May be | G12: =COUNTIF($D$4:$D$12,D12) -> 2 | H12: =COUNTIFS($D$4:$D$12,D12,$F$4:$F$12,F12) -> 1 | I12: =COUNTIF($C$4:$C$12,C14) -> 0 | J12: =COUNTIFS($C$4:$C$12,C12,$D$4:$D$12,D12) -> 1
A13: Count | B13: =COUNT(B4:B12) -> 9 | C13: =COUNTA(C4:C12) -> 9 | D13: =COUNTA(D4:D12) -> 9 | E13: =COUNTA(E4:E12) -> 9 | F13: =COUNTBLANK(F4:F12) -> 1
C14: CountA | F14: CountBlank

Sheet IF Function
A1: IF Function
A3: Sales Figures - December 2020 | H3: Monthly Goal: | I3: 34000
A5: Sales Person | B5: Week 1 | C5: Week 2 | D5: Week 3 | E5: Week 4 | F5: Totals | H5: Was Goal Met? | I5: Bonus Status
A6: H. James | B6: 9550 | C6: 9230 | D6: 8500 | E6: 8965 | F6: =SUM(B6:E6) -> 36245 | H6: =IF(F6>$I$3, "Yes","No") -> Yes | I6: {=IF(AND(H6="Yes",B6:E6>8000),"Applicable","Not Applicable")} -> Applicable | J6: [Bonus applicable only if Goal is Met, and per week revenue is more than 8000]
A7: K. Dunn | B7: 5975 | C7: 6900 | D7: 8500 | E7: 10100 | F7: =SUM(B7:E7) -> 31475 | H7: =IF(F7>$I$3, "Yes","No") -> No | I7: {=IF(AND(H7="Yes",B7:E7>8000),"Applicable","Not Applicable")} -> Not Applicable
A8: L. Carrie | B8: 7425 | C8: 8580 | D8: 9910 | E8: 7512 | F8: =SUM(B8:E8) -> 33427 | H8: =IF(F8>$I$3, "Yes","No") -> No | I8: {=IF(AND(H8="Yes",B8:E8>8000),"Applicable","Not Applicable")} -> Not Applicable
A9: R. Smith | B9: 9560 | C9: 10150 | D9: 10200 | E9: 9795 | F9: =SUM(B9:E9) -> 39705 | H9: =IF(F9>$I$3, "Yes","No") -> Yes | I9: {=IF(AND(H9="Yes",B9:E9>8000),"Applicable","Not Applicable")} -> Applicable
A10: D. O'Brian | B10: 7892 | C10: 7695 | D10: 9520 | E10: 10252 | F10: =SUM(B10:E10) -> 35359 | H10: =IF(F10>$I$3, "Yes","No") -> Yes | I10: {=IF(AND(H10="Yes",B10:E10>8000),"Applicable","Not Applicable")} -> Not Applicable
A11: Weekly Total | B11: =SUM(B6:B10) -> 40402 | C11: =SUM(C6:C10) -> 42555 | D11: =SUM(D6:D10) -> 46630 | E11: =SUM(E6:E10) -> 46624 | F11: =SUM(F6:F10) -> 176211
A13: Current number of sales people who haved reached their goal: | F13: =COUNTIF(H6:H10,H6) -> 3

Sheet SUMIF Function
A1: SUMIF Function
B4: Month | C4: Store # | D4: SKU | E4: Sales | F4: Units | H4: Store # | I4: Total Units | J4: Total Sales
B5: JAN | C5: 1000 | D5: E0028M | E5: =F5*28 -> 9660 | F5: 345 | H5: 3000 | I5: =SUMIF(C5:C274,H5,F5:F274) -> 17538 | J5: =SUMIF(C5:C274,H5,E5:E274) -> 491064
B6: JAN | C6: 1050 | D6: E0028M | E6: =F6*28 -> 5936 | F6: 212 | H6: SKU # | I6: Total Units | J6: Total Sales
B7: JAN | C7: 2000 | D7: E0028M | E7: =F7*28 -> 10136 | F7: 362 | H7: E0032M | I7: =SUMIF(D5:D274,H7,F5:F274) -> 7357 | J7: =SUMIF(D5:D274,H7,E5:E274) -> 205996
B8: JAN | C8: 2050 | D8: E0028M | E8: =F8*28 -> 3388 | F8: 121
B9: JAN | C9: 3000 | D9: E0028M | E9: =F9*28 -> 14056 | F9: 502
B10: JAN | C10: 3050 | D10: E0028M | E10: =F10*28 -> 10136 | F10: 362 | H10: =I10*28 -> 3388 | I10: 121
B11: JAN | C11: 1000 | D11: E0030M | E11: =F11*28 -> 14588 | F11: 521 | H11: =I11*28 -> 15176 | I11: 542
B12: JAN | C12: 1050 | D12: E0030M | E12: =F12*28 -> 6552 | F12: 234 | H12: =I12*28 -> 5964 | I12: 213
B13: JAN | C13: 2000 | D13: E0030M | E13: =F13*28 -> 11788 | F13: 421 | H13: =I13*28 -> 6748 | I13: 241
B14: JAN | C14: 2050 | D14: E0030M | E14: =F14*28 -> 9072 | F14: 324 | H14: =I14*28 -> 11508 | I14: 411
B15: JAN | C15: 3000 | D15: E0030M | E15: =F15*28 -> 3388 | F15: 121 | H15: =I15*28 -> 3416 | I15: 122
B16: JAN | C16: 3050 | D16: E0030M | E16: =F16*28 -> 15176 | F16: 542 | H16: =I16*28 -> 14588 | I16: 521
B17: JAN | C17: 1000 | D17: E0032M | E17: =F17*28 -> 5964 | F17: 213 | H17: =I17*28 -> 17640 | I17: 630
B18: JAN | C18: 1050 | D18: E0032M | E18: =F18*28 -> 6748 | F18: 241 | H18: =I18*28 -> 9856 | I18: 352
B19: JAN | C19: 2000 | D19: E0032M | E19: =F19*28 -> 11508 | F19: 411
B20: JAN | C20: 2050 | D20: E0032M | E20: =F20*28 -> 3416 | F20: 122 | H20: SUB-TOTAL | I20: =SUBTOTAL(1,I10:I18) -> 350.33333
B21: JAN | C21: 3000 | D21: E0032M | E21: =F21*28 -> 14588 | F21: 521
B22: JAN | C22: 3050 | D22: E0032M | E22: =F22*28 -> 17640 | F22: 630
B23: JAN | C23: 1000 | D23: E0034M | E23: =F23*28 -> 9856 | F23: 352
B24: JAN | C24: 1050 | D24: E0034M | E24: =F24*28 -> 9016 | F24: 322
B25: JAN | C25: 2000 | D25: E0034M | E25: =F25*28 -> 17976 | F25: 642
B26: JAN | C26: 2050 | D26: E0034M | E26: =F26*28 -> 14616 | F26: 522
B27: JAN | C27: 3000 | D27: E0034M | E27: =F27*28 -> 3724 | F27: 133
B28: JAN | C28: 3050 | D28: E0034M | E28: =F28*28 -> 12712 | F28: 454
B29: JAN | C29: 1000 | D29: E0036M | E29: =F29*28 -> 16828 | F29: 601
B30: JAN | C30: 1050 | D30: E0036M | E30: =F30*28 -> 14056 | F30: 502
B31: JAN | C31: 2000 | D31: E0036M | E31: =F31*28 -> 8456 | F31: 302
B32: JAN | C32: 2050 | D32: E0036M | E32: =F32*28 -> 17808 | F32: 636
... B274: MAR | C274: 3050 | D274: C0036M | E274: =F274*28 -> 11256 | F274: 402

Sheet Sum-Count
A1: SUMIFS, AVERAGEIFS & COUNTIFS
B3: Company | C3: Business Unit | D3: Main Unit | E3: Red Flag | F3: Revenue | I3: Question | J3: Find the solution to the following
B4: Entity A | C4: BU_1 | D4: VC_A | E4: 1 | F4: =10200 -> 10200 | G4: =IF(F4<13000,F4,0) -> 10200 | I4: 1 | J4: Total revenue of red flag companies | K4: =SUMIF(E4:E29,E4,F4:F29) -> 72000
B5: Entity B | C5: BU_1 | D5: VC_A | F5: =F4*1.2 -> 12240 | G5: =IF(F5<13000,F5,0) -> 12240 | I5: 2 | J5: Total revenue of companies below 13,000 | K5: =SUMIF(B4:F29,"F4:F29<13000") -> 0
B6: Entity C | C6: BU_1 | D6: VC_A | F6: =F5*1.2 -> 14688 | G6: =IF(F6<13000,F6,0) -> 0 | I6: 3 | J6: Total revenue that matches the below criteria:
B7: Entity D | C7: BU_1 | D7: VC_A | F7: =F6*1.2 -> 17625.6 | G7: =IF(F7<13000,F7,0) -> 0 | I7: 4 | J7: Main Unit is | K7: VC_C
B8: Entity E | C8: BU_2 | D8: VC_A | E8: 1 | F8: 10300 | G8: =IF(F8<13000,F8,0) -> 10300 | I8: 5 | J8: Red flag entity | K8: 1
B9: Entity F | C9: BU_2 | D9: VC_A | F9: =F8*1.2 -> 12360 | G9: =IF(F9<13000,F9,0) -> 12360 | I9: 6 | J9: Answer: | K9: =SUMIFS(F4:F29,D4:D29,K7,E4:E29,K8) -> 41100
B10: Entity G | C10: BU_2 | D10: VC_A | F10: =F9*1.2 -> 14832 | G10: =IF(F10<13000,F10,0) -> 0 | I10: 7
B11: Entity H | C11: BU_2 | D11: VC_A | F11: =F10*1.2 -> 17798.4 | G11: =IF(F11<13000,F11,0) -> 0 | I11: 8 | J11: How many companies match the below criteria
B12: Entity I | C12: BU_3 | D12: VC_B | E12: 1 | F12: 10400 | G12: =IF(F12<13000,F12,0) -> 10400 | I12: 9 | J12: In main unit | K12: VC_b
B13: Entity J | C13: BU_3 | D13: VC_B | F13: =F12*1.2 -> 12480 | G13: =IF(F13<13000,F13,0) -> 12480 | I13: 10 | J13: have revenue equal or above | K13: 20000
B14: Entity K | C14: BU_3 | D14: VC_B | F14: =F13*1.2 -> 14976 | G14: =IF(F14<13000,F14,0) -> 0 | I14: 11 | J14: Answer: | K14: =COUNTIFS(D4:D29,K12,F4:F29,">=20000") -> 5
B15: Entity L | C15: BU_4 | D15: VC_B | F15: 20000 | G15: =IF(F15<13000,F15,0) -> 0
B16: Entity M | C16: BU_4 | D16: VC_B | F16: =F15*1.2 -> 24000 | G16: =IF(F16<13000,F16,0) -> 0
B17: Entity N | C17: BU_4 | D17: VC_B | F17: =F16*1.2 -> 28800 | G17: =IF(F17<13000,F17,0) -> 0
B18: Entity O | C18: BU_4 | D18: VC_B | F18: =F17*1.2 -> 34560 | G18: =IF(F18<13000,F18,0) -> 0 | H18: =CONCATENATE(C18,D18) -> BU_4VC_B
B19: Entity P | C19: BU_5 | D19: VC_B | F19: =F18*1.2 -> 41472 | G19: =IF(F19<13000,F19,0) -> 0
B20: Entity Q | C20: BU_6 | D20: VC_C | F20: =F19*1.2 -> 49766.4 | G20: =IF(F20<13000,F20,0) -> 0
B21: Entity R | C21: BU_6 | D21: VC_C | E21: 1 | F21: 10500 | G21: =IF(F21<13000,F21,0) -> 10500
B22: Entity S | C22: BU_6 | D22: VC_C | F22: =F7*1.2 -> 21150.72 | G22: =IF(F22<13000,F22,0) -> 0
B23: Entity T | C23: BU_6 | D23: VC_C | F23: =F22*1.2 -> 25380.864 | G23: =IF(F23<13000,F23,0) -> 0
B24: Entity U | C24: BU_7 | D24: VC_C | F24: =F23*1.2 -> 30457.037 | G24: =IF(F24<13000,F24,0) -> 0
B25: Entity V | C25: BU_7 | D25: VC_C | E25: 1 | F25: 10200 | G25: =IF(F25<13000,F25,0) -> 10200
B26: Entity W | C26: BU_7 | D26: VC_C | F26: =F25*1.2 -> 12240 | G26: =IF(F26<13000,F26,0) -> 12240
B27: Entity X | C27: BU_7 | D27: VC_C | F27: =F26*1.2 -> 14688 | G27: =IF(F27<13000,F27,0) -> 0
B28: Entity Y | C28: BU_8 | D28: VC_C | E28: 1 | F28: 10100 | G28: =IF(F28<13000,F28,0) -> 10100
B29: Entity Z | C29: BU_8 | D29: VC_C | E29: 1 | F29: 10300 | G29: =IF(F29<13000,F29,0) -> 10300
G30: =SUM(G4:G29) -> 121320

Sheet LEFT RIGHT MID Functions
A1: LEFT RIGHT MID Function
A3: SKU Number | B3: Product Name | C3: Retail Price | E3: Supplier ID | F3: Part # | G3: Product Code | H3: Num Chars | I3: Lower | J3: Upper
A4: ACM110WW | B4: Windshield Wipers #110 | C4: 13.65 | E4: =LEFT(A4,3) -> ACM | F4: =MID(A4,4,3) -> 110 | G4: =RIGHT(A4,2) -> WW | H4: =LEN(B4) -> 22 | I4: =LOWER(B4) -> windshield wipers #110 | J4: =UPPER(B4) -> WINDSHIELD WIPERS #110
A5: ACM111WWq | B5: Windshield Wipers #111 | C5: 12.19 | E5: =LEFT(A5,3) -> ACM | F5: =MID(A5,4,3) -> 111 | G5: =RIGHT(A5,2) -> Wq | H5: =LEN(B5) -> 22 | I5: =LOWER(B5) -> windshield wipers #111 | J5: =UPPER(B5) -> WINDSHIELD WIPERS #111
A6: ACM150WW | B6: Windshield Wipers #150 | C6: 10.89 | E6: =LEFT(A6,3) -> ACM | F6: =MID(A6,4,3) -> 150 | G6: =RIGHT(A6,2) -> WW | H6: =LEN(B6) -> 22 | I6: =LOWER(B6) -> windshield wipers #150 | J6: =UPPER(B6) -> WINDSHIELD WIPERS #150
A7: ACM321DP | B7: Drain Plug #321 | C7: 9.75 | E7: =LEFT(A7,3) -> ACM | F7: =MID(A7,4,3) -> 321 | G7: =RIGHT(A7,2) -> DP | H7: =LEN(B7) -> 15 | I7: =LOWER(B7) -> drain plug #321 | J7: =UPPER(B7) -> DRAIN PLUG #321
A8: ACM322DP | B8: Drain Plug #322 | C8: 9.59 | E8: =LEFT(A8,3) -> ACM | F8: =MID(A8,4,3) -> 322 | G8: =RIGHT(A8,2) -> DP | H8: =LEN(B8) -> 15 | I8: =LOWER(B8) -> drain plug #322 | J8: =UPPER(B8) -> DRAIN PLUG #322
A9: ACM325DP | B9: Drain Plug #325 | C9: 10.4 | E9: =LEFT(A9,3) -> ACM | F9: =MID(A9,4,3) -> 325 | G9: =RIGHT(A9,2) -> DP | H9: =LEN(B9) -> 15 | I9: =LOWER(B9) -> drain plug #325 | J9: =UPPER(B9) -> DRAIN PLUG #325
A10: ACM330DP | B10: Drain Plug #330 | C10: 10.56 | E10: =LEFT(A10,3) -> ACM | F10: =MID(A10,4,3) -> 330 | G10: =RIGHT(A10,2) -> DP | H10: =LEN(B10) -> 15 | I10: =LOWER(B10) -> drain plug #330 | J10: =UPPER(B10) -> DRAIN PLUG #330
A11: ACM450DP | B11: Drain Plug #450 | C11: 9.75 | E11: =LEFT(A11,3) -> ACM | F11: =MID(A11,4,3) -> 450 | G11: =RIGHT(A11,2) -> DP | H11: =LEN(B11) -> 15 | I11: =LOWER(B11) -> drain plug #450 | J11: =UPPER(B11) -> DRAIN PLUG #450
A12: ACM460DP | B12: Drain Plug #460 | C12: 9.75 | E12: =LEFT(A12,3) -> ACM | F12: =MID(A12,4,3) -> 460 | G12: =RIGHT(A12,2) -> DP | H12: =LEN(B12) -> 15 | I12: =LOWER(B12) -> drain plug #460 | J12: =UPPER(B12) -> DRAIN PLUG #460
A13: AST530OL | B13: 5W30 | C13: 4.06 | E13: =LEFT(A13,3) -> AST | F13: =MID(A13,4,3) -> 530 | G13: =RIGHT(A13,2) -> OL | H13: =LEN(B13) -> 4 | I13: =LOWER(B13) -> 5w30 | J13: =UPPER(B13) -> 5W30
A14: AST100TF | B14: Automatic Transmission Fluid | C14: 5.04 | E14: =LEFT(A14,3) -> AST | F14: =MID(A14,4,3) -> 100 | G14: =RIGHT(A14,2) -> TF | H14: =LEN(B14) -> 28 | I14: =LOWER(B14) -> automatic transmission fluid | J14: =UPPER(B14) -> AUTOMATIC TRANSMISSION FLUID
A15: AST130OL | B15: 10W30 | C15: 3.9 | E15: =LEFT(A15,3) -> AST | F15: =MID(A15,4,3) -> 130 | G15: =RIGHT(A15,2) -> OL | H15: =LEN(B15) -> 5 | I15: =LOWER(B15) -> 10w30 | J15: =UPPER(B15) -> 10W30
... A27: TRA610OF | B27: Oil Filter #610 | C27: 6.14 | E27: =LEFT(A27,3) -> TRA | F27: =MID(A27,4,3) -> 610 | G27: =RIGHT(A27,2) -> OF | H27: =LEN(B27) -> 15 | I27: =LOWER(B27) -> oil filter #610 | J27: =UPPER(B27) -> OIL FILTER #610
B29: A business Analyst act as a bridge between business stakeholders and the IT team. They analyze business processses, gather requirements and translate them into functional specifications to ensure a project meets its objectives

Sheet Textjoin textsplit
A1: TEXT Functions
E4: Concatenate | F4: TextJoin | G4: Arraytotext
B5: Last Name | C5: First Name | E5: Full Name: | F5: Full Name: | G5: Names
B6: Smith | C6: Howard | E6: =CONCATENATE(C6," ",B6) -> Howard Smith | F6: =_xlfn.TEXTJOIN(" ",TRUE,B6,C6) -> Smith Howard | G6: =_xlfn.ARRAYTOTEXT(B6:B9,0) -> Smith, Gonzales, Scote, Kane
B7: Gonzales | C7: Joe | E7: =CONCATENATE(C7," ",B7) -> Joe Gonzales | F7: =_xlfn.TEXTJOIN(" ",TRUE,B7,C7) -> Gonzales Joe
B8: Scote | C8: Gail | E8: =CONCATENATE(C8," ",B8) -> Gail Scote | F8: =_xlfn.TEXTJOIN(" ",TRUE,B8,C8) -> Scote Gail | I8: Textsplit in row | J8: Textsplit in col
B9: Kane | C9: Sheryl | E9: =CONCATENATE(C9," ",B9) -> Sheryl Kane | F9: =_xlfn.TEXTJOIN(" ",TRUE,B9,C9) -> Kane Sheryl | I9: Names | J9: Names
B10: Hapsbuch | C10: Kendrick | E10: =CONCATENATE(C10," ",B10) -> Kendrick Hapsbuch | F10: =_xlfn.TEXTJOIN(" ",TRUE,B10,C10) -> Hapsbuch Kendrick | I10: Pratik Ranjeet Naigaonkar | J10: {=_xlfn.TEXTSPLIT(I10," ",,,0)} -> Pratik | K10: Ranjeet | L10: Naigaonkar
B11: Henders | C11: Mark | E11: =CONCATENATE(C11," ",B11) -> Mark Henders | F11: =_xlfn.TEXTJOIN(" ",TRUE,B11,C11) -> Henders Mark | I11: {=_xlfn.TEXTSPLIT(I10,," ",,)} -> Pratik
B12: Atherton | C12: Katie | E12: =CONCATENATE(C12," ",B12) -> Katie Atherton | F12: =_xlfn.TEXTJOIN(" ",TRUE,B12,C12) -> Atherton Katie | I12: Ranjeet
B13: Bellwood | C13: Frank | E13: =CONCATENATE(C13," ",B13) -> Frank Bellwood | F13: =_xlfn.TEXTJOIN(" ",TRUE,B13,C13) -> Bellwood Frank | I13: Naigaonkar
B14: Cooper | C14: Linda | E14: =CONCATENATE(C14," ",B14) -> Linda Cooper | F14: =_xlfn.TEXTJOIN(" ",TRUE,B14,C14) -> Cooper Linda
B15: Cronwith | C15: Brent | E15: =CONCATENATE(C15," ",B15) -> Brent Cronwith | F15: =_xlfn.TEXTJOIN(" ",TRUE,B15,C15) -> Cronwith Brent
B16: Simpson | C16: Sandrae | E16: =CONCATENATE(C16," ",B16) -> Sandrae Simpson | F16: =_xlfn.TEXTJOIN(" ",TRUE,B16,C16) -> Simpson Sandrae
B17: Sindole | C17: Randy | E17: =CONCATENATE(C17," ",B17) -> Randy Sindole | F17: =_xlfn.TEXTJOIN(" ",TRUE,B17,C17) -> Sindole Randy
B18: Smith | C18: Ellen | E18: =CONCATENATE(C18," ",B18) -> Ellen Smith | F18: =_xlfn.TEXTJOIN(" ",TRUE,B18,C18) -> Smith Ellen
B19: Vuanuo | C19: Tuome | E19: =CONCATENATE(C19," ",B19) -> Tuome Vuanuo | F19: =_xlfn.TEXTJOIN(" ",TRUE,B19,C19) -> Vuanuo Tuome
B20: Szcznyck | C20: Tadeuz | E20: =CONCATENATE(C20," ",B20) -> Tadeuz Szcznyck | F20: =_xlfn.TEXTJOIN(" ",TRUE,B20,C20) -> Szcznyck Tadeuz
B21: Wu | C21: Tammy | E21: =CONCATENATE(C21," ",B21) -> Tammy Wu | F21: =_xlfn.TEXTJOIN(" ",TRUE,B21,C21) -> Wu Tammy
C27: Textjoin
B28: Name | C28: Name
B29: Smith, Scote, Kane | C29: =_xlfn.TEXTJOIN(", ",TRUE,B29,B30,B31) -> Smith, Scote, Kane, Joey, Sindole, Wu Yung, Cooper, Ray
B30: Joey, Sindole, Wu Yung
B31: Cooper, Ray
E32: Textsplit+Textjoin
E33: Name
E34: {=_xlfn.TEXTSPLIT(C29,,", ",TRUE)} -> Smith | F34: {=_xlfn.TEXTSPLIT(C29,," ",TRUE)} -> Smith,
E35: Scote | F35: Scote,
E36: Kane | F36: Kane,
E37: Joey | F37: Joey,
E38: Sindole | F38: Sindole,
E39: Wu Yung | F39: Wu
E40: Cooper | F40: Yung,
E41: Ray | F41: Cooper,
F42: Ray
B44: Name
B45: Smith Scote Kane Cooper Ray
E46: textsplit(char(10)
E47: Name
E48: {=_xlfn.TEXTSPLIT(B45,CHAR(9),,,)} -> Smith Scote Kane Cooper Ray
...

Sheet Data list for Dashboard
A1: Insight from data
A4: Product | B4: Category | C4: Cost | D4: Revenue | E4: Profit | F4: Date
A5: Paracetamol | B5: Analgesic | C5: 3450 | D5: 8625 | E5: 5175 | F5: 43770
A6: Losartan | B6: CVS | C6: 4304 | D6: 10760 | E6: 6456 | F6: 43800
A7: Dizepam | B7: CNS | C7: 4698 | D7: 11745 | E7: 7047 | F7: 43709 | H7: What insight can be drawn using the given data?
A8: Sumatriptan | B8: CNS | C8: 2456 | D8: 6140 | E8: 3684 | F8: 43739 | H8: Prepare a pivot using a given data
A9: Zolmitriptan | B9: CNS | C9: 2778 | D9: 6945 | E9: 4167 | F9: 43739
A10: Azelastine | B10: Respiratory | C10: 3604 | D10: 9010 | E10: 5406 | F10: 43800
A11: Telmisartan | B11: CVS | C11: 4598 | D11: 11495 | E11: 6897 | F11: 43739
A12: Levodopa | B12: CNS | C12: 2808 | D12: 7020 | E12: 4212 | F12: 43770
A13: Carbidopa | B13: CNS | C13: 4940 | D13: 12350 | E13: 7410 | F13: 43709
A14: Ibuprofen | B14: Analgesic | C14: 4444 | D14: 8715 | E14: 5229 | F14: 43739
A15: Cisplatin | B15: Anticancer | C15: 9423 | D15: 11110 | E15: 6666 | F15: 43770
A16: Etopposide | B16: Anticancer | C16: 7083.2 | D16: 345 | E16: 276 | F16: 43739
A17: Salbutamol | B17: Respiratory | C17: 256.6 | D17: 2851 | E17: 2280.8 | F17: 43739
A18: Amoxicillin | B18: Respiratory | C18: 322.2 | D18: 1283 | E18: 1026.4 | F18: 43709

Sheet Sales Data Pivote
A1: Customer | B1: Order ID | C1: Product | D1: Units Sold | E1: Date | F1: Rev | G1: Our cost | J1: Customer ID | K1: Total Revenue | L1: # of orders
A2: 3 | B2: 397386 | C2: White Chocolate Macadamia Nut | D2: 3997.5 | E2: 43831 | F2: 23985 | G2: 10993.125 | J2: 1 | K2: =SUMIFS(F:F,A:A,J2) -> 521251 | L2: =COUNTIFS(A:A,J2) -> 92
A3: 5 | B3: 613058 | C3: White Chocolate Macadamia Nut | D3: 3864 | E3: 43922 | F3: 23184 | G3: 10626 | J3: 2 | K3: =SUMIFS(F:F,A:A,J3) -> 903407 | L3: =COUNTIFS(A:A,J3) -> 132
A4: 4 | B4: 766402 | C4: White Chocolate Macadamia Nut | D4: 3850.5 | E4: 43922 | F4: 23103 | G4: 10588.875 | J4: 3 | K4: =SUMIFS(F:F,A:A,J4) -> 1431191 | L4: =COUNTIFS(A:A,J4) -> 206
A5: 4 | B5: 710702 | C5: White Chocolate Macadamia Nut | D5: 3793.5 | E5: 44013 | F5: 22761 | G5: 10432.125 | J5: 4 | K5: =SUMIFS(F:F,A:A,J5) -> 1108643 | L5: =COUNTIFS(A:A,J5) -> 156
A6: 5 | B6: 283378 | C6: Chocolate Chip | D6: 4492.5 | E6: 43922 | F6: 22462.5 | G6: 8985 | J6: 5 | K6: =SUMIFS(F:F,A:A,J6) -> 725758.5 | L6: =COUNTIFS(A:A,J6) -> 114
A7: 3 | B7: 239419 | C7: Chocolate Chip | D7: 4251 | E7: 43831 | F7: 21255 | G7: 8502
A8: 4 | B8: 739483 | C8: Oatmeal Raisin | D8: 4219.5 | E8: 43922 | F8: 21097.5 | G8: 9282.9
A9: 3 | B9: 253399 | C9: Chocolate Chip | D9: 4026 | E9: 44013 | F9: 20130 | G9: 8052
A10: 4 | B10: 361305 | C10: Chocolate Chip | D10: 3945 | E10: 43831 | F10: 19725 | G10: 7890
A11: 2 | B11: 603195 | C11: Chocolate Chip | D11: 3801 | E11: 43922 | F11: 19005 | G11: 7602
A12: 2 | B12: 643111 | C12: Chocolate Chip | D12: 3675 | E12: 43922 | F12: 18375 | G12: 7350
A13: 4 | B13: 861720 | C13: White Chocolate Macadamia Nut | D13: 2966 | E13: 43739 | F13: 17796 | G13: 8156.5
A14: 3 | B14: 272552 | C14: Oatmeal Raisin | D14: 3520.5 | E14: 43922 | F14: 17602.5 | G14: 7745.1
A15: 4 | B15: 459019 | C15: Chocolate Chip | D15: 3513 | E15: 44013 | F15: 17565 | G15: 7026
A16: 2 | B16: 628402 | C16: Chocolate Chip | D16: 3495 | E16: 43831 | F16: 17475 | G16: 6990
A17: 3 | B17: 567117 | C17: White Chocolate Macadamia Nut | D17: 2907 | E17: 43983 | F17: 17442 | G17: 7994.25
A18: 2 | B18: 426268 | C18: White Chocolate Macadamia Nut | D18: 2877 | E18: 44105 | F18: 17262 | G18: 7911.75
... A701: 2 | B701: 205221 | C701: Fortune Cookie | D701: 200 | E701: 43952 | F701: 200 | G701: 100

Sheet Array
A1: Introduction to Array
B4: 1 | C4: 2 | D4: 3 | E4: 4 | F4: 5 | G4: 6 | H4: 7 | I4: 8
B5: 2 | C5: {=B5:B11*C4:I4} -> 4 | D5: 6 | E5: 8 | F5: 10 | G5: 12 | H5: 14 | I5: 16
B6: 3 | C6: 6 | D6: 9 | E6: 12 | F6: 15 | G6: 18 | H6: 21 | I6: 24
B7: 4 | C7: 8 | D7: 12 | E7: 16 | F7: 20 | G7: 24 | H7: 28 | I7: 32
B8: 5 | C8: 10 | D8: 15 | E8: 20 | F8: 25 | G8: 30 | H8: 35 | I8: 40
B9: 6 | C9: 12 | D9: 18 | E9: 24 | F9: 30 | G9: 36 | H9: 42 | I9: 48
B10: 7 | C10: 14 | D10: 21 | E10: 28 | F10: 35 | G10: 42 | H10: 49 | I10: 56
B11: 8 | C11: 16 | D11: 24 | E11: 32 | F11: 40 | G11: 48 | H11: 56 | I11: 64

Sheet ArrayForConversion
A1: CURRENCY CONVERSION TABLE
A3: Currency | C3: {=TRANSPOSE(1/B4:B14)} -> 1 | D3: 1.3086847 | E3: 1.2860545 | F3: 0.99840953 | G3: 6.6516782 | H3: 0.85958506 | I3: 0.76170396 | J3: 64.884506 | K3: 114.15525 | L3: 4.2407562 | M3: 1.3678637
A4: USD | B4: 1 | C4: {=TRANSPOSE(B4/$B$4:$B$14)} -> 1 | D4: 1.3086847 | E4: 1.2860545 | F4: 0.99840953 | G4: 6.6516782 | H4: 0.85958506 | I4: 0.76170396 | J4: 64.884506 | K4: 114.15525 | L4: 4.2407562 | M4: 1.3678637
A5: AUD | B5: =INDEX('[1]Current Rates'!$C$4:$C$13,MATCH('[1]Conversion Table'!A5,rateCodes,0)) -> 0.764126 | C5: {=TRANSPOSE(B5/$B$4:$B$14)} -> 0.764126 | D5: 1 | E5: 0.98270771 | F5: 0.76291068 | G5: 5.0827203 | H5: 0.65683129 | I5: 0.5820378 | J5: 49.579938 | K5: 87.228995 | L5: 3.2404721 | M5: 1.0452202
A6: CAD | B6: =INDEX('[1]Current Rates'!$C$4:$C$13,MATCH('[1]Conversion Table'!A6,rateCodes,0)) -> 0.777572 | C6: {=TRANSPOSE(B6/$B$4:$B$14)} -> 0.777572 | D6: 1.0175966 | E6: 1 | F6: 0.7763353 | G6: 5.1721587 | H6: 0.66838928 | I6: 0.59227967 | J6: 50.452375 | K6: 88.763927 | L6: 3.2974933 | M6: 1.0636125
A7: CHF | B7: =INDEX('[1]Current Rates'!$C$4:$C$13,MATCH('[1]Conversion Table'!A7,rateCodes,0)) -> 1.001593 | C7: {=TRANSPOSE(B7/$B$4:$B$14)} -> 1.001593 | D7: 1.3107694 | E7: 1.2881032 | F7: 1 | G7: 6.6622743 | H7: 0.86095438 | I7: 0.76291736 | J7: 64.987867 | K7: 114.3371 | L7: 4.2475117 | M7: 1.3700427
A8: CNY | B8: =INDEX('[1]Current Rates'!$C$4:$C$13,MATCH('[1]Conversion Table'!A8,rateCodes,0)) -> 0.150338 | C8: {=TRANSPOSE(B8/$B$4:$B$14)} -> 0.150338 | D8: 0.19674504 | E8: 0.19334287 | F8: 0.15009889 | G8: 1 | H8: 0.1292283 | I8: 0.11451305 | J8: 9.7546068 | K8: 17.161872 | L8: 0.63754681 | M8: 0.20564189
A9: EUR | B9: =INDEX('[1]Current Rates'!$C$4:$C$13,MATCH('[1]Conversion Table'!A9,rateCodes,0)) -> 1.163352 | C9: {=TRANSPOSE(B9/$B$4:$B$14)} -> 1.163352 | D9: 1.522461 | E9: 1.4961341 | F9: 1.1615017 | G9: 7.7382432 | H9: 1 | I9: 0.88612983 | J9: 75.483519 | K9: 132.80274 | L9: 4.9334922 | M9: 1.591307
A10: GBP | B10: =INDEX('[1]Current Rates'!$C$4:$C$13,MATCH('[1]Conversion Table'!A10,rateCodes,0)) -> 1.312846 | C10: {=TRANSPOSE(B10/$B$4:$B$14)} -> 1.312846 | D10: 1.7181015 | E10: 1.6883916 | F10: 1.310758 | G10: 8.7326291 | H10: 1.1285028 | I10: 1 | J10: 85.183364 | K10: 149.86826 | L10: 5.5674598 | M10: 1.7957944
A11: INR | B11: =INDEX('[1]Current Rates'!$C$4:$C$13,MATCH('[1]Conversion Table'!A11,rateCodes,0)) -> 0.015412 | C11: {=TRANSPOSE(B11/$B$4:$B$14)} -> 0.015412 | D11: 0.020169448 | E11: 0.019820673 | F11: 0.015387488 | G11: 0.10251566 | H11: 0.013247925 | I11: 0.011739381 | J11: 1 | K11: 1.7593607 | L11: 0.065358535 | M11: 0.021081515
A12: JPY | B12: =INDEX('[1]Current Rates'!$C$4:$C$13,MATCH('[1]Conversion Table'!A12,rateCodes,0)) -> 0.00876 | C12: {=TRANSPOSE(B12/$B$4:$B$14)} -> 0.00876 | D12: 0.011464078 | E12: 0.011265838 | F12: 0.0087460675 | G12: 0.058268701 | H12: 0.0075299651 | I12: 0.0066725267 | J12: 0.56838827 | K12: 1 | L12: 0.037149024 | M12: 0.011982486
A13: MYR | B13: =INDEX('[1]Current Rates'!$C$4:$C$13,MATCH('[1]Conversion Table'!A13,rateCodes,0)) -> 0.235807 | C13: {=TRANSPOSE(B13/$B$4:$B$14)} -> 0.235807 | D13: 0.30859701 | E13: 0.30326066 | F13: 0.23543196 | G13: 1.5685123 | H13: 0.20269617 | I13: 0.17961513 | J13: 15.300221 | K13: 26.918607 | L13: 1 | M13: 0.32255183
A14: SGD | B14: =INDEX('[1]Current Rates'!$C$4:$C$13,MATCH('[1]Conversion Table'!A14,rateCodes,0)) -> 0.731067 | C14: {=TRANSPOSE(B14/$B$4:$B$14)} -> 0.731067 | D14: 0.95673619 | E14: 0.94019203 | F14: 0.72990426 | G14: 4.8628224 | H14: 0.62841427 | I14: 0.55685663 | J14: 47.434921 | K14: 83.455137 | L14: 3.1002769 | M14: 1

Sheet Current Rates
A1: CURRENT RATES
AA2: US Dollar | AB2: USD
A3: US Dollar | B3: 1.00 USD | C3: inv. 1.00 USD | D3: =_xlfn.IFNA(VLOOKUP(A3,CodeLookup,2,0),"") -> USD | AA3: Australian Dollar | AB3: AUD
A4: Euro | B4: 0.859585 | C4: 1.163352 | D4: =_xlfn.IFNA(VLOOKUP(A4,CodeLookup,2,0),"") -> EUR | AA4: Canadian Dollar | AB4: CAD
A5: British Pound | B5: 0.761704 | C5: 1.312846 | D5: =_xlfn.IFNA(VLOOKUP(A5,CodeLookup,2,0),"") -> GBP | AA5: Swiss Franc | AB5: CHF
A6: Indian Rupee | B6: 64.88465 | C6: 0.015412 | D6: =_xlfn.IFNA(VLOOKUP(A6,CodeLookup,2,0),"") -> INR | AA6: Chinese Yuan Renminbi | AB6: CNY
A7: Australian Dollar | B7: 1.308684 | C7: 0.764126 | D7: =_xlfn.IFNA(VLOOKUP(A7,CodeLookup,2,0),"") -> AUD | AA7: Euro | AB7: EUR
A8: Canadian Dollar | B8: 1.286055 | C8: 0.777572 | D8: =_xlfn.IFNA(VLOOKUP(A8,CodeLookup,2,0),"") -> CAD | AA8: British Pound | AB8: GBP
A9: Singapore Dollar | B9: 1.367864 | C9: 0.731067 | D9: =_xlfn.IFNA(VLOOKUP(A9,CodeLookup,2,0),"") -> SGD | AA9: Indian Rupee | AB9: INR
A10: Swiss Franc | B10: 0.998409 | C10: 1.001593 | D10: =_xlfn.IFNA(VLOOKUP(A10,CodeLookup,2,0),"") -> CHF | AA10: Japanese Yen | AB10: JPY
A11: Malaysian Ringgit | B11: 4.240755 | C11: 0.235807 | D11: =_xlfn.IFNA(VLOOKUP(A11,CodeLookup,2,0),"") -> MYR | AA11: Malaysian Ringgit | AB11: MYR
A12: Japanese Yen | B12: 114.15768 | C12: 0.00876 | D12: =_xlfn.IFNA(VLOOKUP(A12,CodeLookup,2,0),"") -> JPY | AA12: Singapore Dollar | AB12: SGD
A13: Chinese Yuan Renminbi | B13: 6.651685 | C13: 0.150338 | D13: =_xlfn.IFNA(VLOOKUP(A13,CodeLookup,2,0),"") -> CNY
A21: http://www.x-rates.com/table/?from=USD&amount=1

Sheet SecondaryAxis
A1: Adding a Secondary axis
B3: Jan | C3: Feb | D3: Mar | E3: Apr | F3: May | G3: Jun | H3: Jul | I3: Aug | J3: Sep | K3: Oct | L3: Nov | M3: Dec
A4: Average Temperature(oC) | B4: 6 | C4: 7 | D4: 12 | E4: 21 | F4: 24 | G4: 25 | H4: 22 | I4: 21 | J4: 19 | K4: 12 | L4: 7 | M4: 2
A5: Average Rainfall (mm) | B5: 90 | C5: 70 | D5: 80 | E5: 50 | F5: 89 | G5: 79 | H5: 88 | I5: 87 | J5: 60 | K5: 95 | L5: 93 | M5: 77

Sheet Xlookup Emp List
A1: Emp ID | B1: Last Name | C1: First Name | D1: Dept | E1: E-mail | F1: Phone Ext | G1: Location | H1: Hire Date | I1: Pay Rate
A2: 1054 | B2: Smith | C2: Howard | D2: AT | E2: howards | F2: 148 | G2: Building 1 | H2: 33344 | I2: 11.25
A3: 1056 | B3: Gonzales | C3: Joe | D3: AT | E3: joeg | F3: 121 | G3: Building 1 | H3: 29153 | I3: 12.25
A4: 1067 | B4: Scote | C4: Gail | D4: AT | E4: gails | F4: 123 | G4: Building 1 | H4: 32040 | I4: 14.55 | K4: Min
A5: 1075 | B5: Kane | C5: Sheryl | D5: AD | E5: sherylk | F5: 126 | G5: Building 2 | H5: 33823 | I5: 11.25 | K5: Mode
A6: 1078 | B6: Hapsbuch | C6: Kendrick | D6: AC | E6: kendrickh | F6: 101 | G6: Building 2 | H6: 31503 | I6: 10.2 | K6: Median
A7: 1152 | B7: Henders | C7: Mark | D7: AD | E7: markh | F7: 123 | G7: Building 2 | H7: 32894 | I7: 12.25 | K7: Avg
A8: 1196 | B8: Atherton | C8: Katie | D8: HR | E8: katiea | F8: 289 | G8: Building 3 | H8: 35886 | I8: 9.95
A9: 1284 | B9: Bellwood | C9: Frank | D9: MK | E9: frankb | F9: 124 | G9: Building 1 | H9: 31051 | I9: 12.3 | K9: Data Validation
A10: 1290 | B10: Cooper | C10: Linda | D10: AD | E10: lindac | F10: 113 | G10: Building 2 | H10: 31050 | I10: 13.25 | K10: 1. Column D- Give Dropdown
A11: 1293 | B11: Cronwith | C11: Brent | D11: HR | E11: brentc | F11: 205 | G11: Building 3 | H11: 30939 | I11: 10.2 | K11: 2. Column F- data entered should be strictly 3 in numbers
A12: 1299 | B12: Simpson | C12: Sandrae | D12: MF | E12: sandraes | F12: 127 | G12: Building 1 | H12: 32863 | I12: 12.2 | K12: 3. Col H- date should be between 1 Jan 24 to 31 Jan 24
A13: 1302 | B13: Sindole | C13: Randy | D13: MK | E13: randys | F13: 139 | G13: Building 1 | H13: 30900 | I13: 14.25 | K13: 4. Column C- Popup Message "write in Title case only"
A14: 1310 | B14: Smith | C14: Ellen | D14: MF | E14: ellens | F14: 137 | G14: Building 1 | H14: 31689 | I14: 11.5 | K14: 5. Column F- Give error message "Only 3 digits accepted"
A15: 1329 | B15: Vuanuo | C15: Tuome | D15: AC | E15: tuomev | F15: 151 | G15: Building 2 | H15: 32561 | I15: 10.35 | K15: 6. Column C - Clear the applied data validation
A16: 1333 | B16: Szcznyck | C16: Tadeuz | D16: HR | E16: tadeuzs | F16: 122 | G16: Building 3 | H16: 32979 | I16: 10.15
A17: 1368 | B17: Wu | C17: Tammy | D17: AD | E17: tammyw | F17: 132 | G17: Building 2 | H17: 30386 | I17: 12.25
A18: 1509 | B18: Kegler | C18: Pam | D18: AT | E18: pamk | F18: 135 | G18: Building 1 | H18: 31217 | I18: 13.25
A19: 1516 | B19: Bell | C19: Tom | D19: AC | E19: tomb | F19: 105 | G19: Building 2 | H19: 31112 | I19: 9.5
A20: 1529 | B20: Kellerman | C20: Tommie | D20: MK | E20: tomk | F20: 129 | G20: Building 1 | H20: 31805 | I20: 11.3
A21: 1656 | B21: Kourios | C21: Theo | D21: MF | E21: theok | F21: 149 | G21: Building 1 | H21: 32125 | I21: 12.35
A22: 1672 | B22: Dixon-Waite | C22: Sherrie | D22: MF | E22: sherried | F22: 114 | G22: Building 1 | H22: 32979 | I22: 11.9
A23: 1673 | B23: Boughton | C23: Frank | D23: AD | E23: fboughton | F23: 112 | G23: Building 2 | H23: 33688 | I23: 11.85
A24: 1676 | B24: Miller | C24: Janet | D24: MK | E24: janetm | F24: 115 | G24: Building 1 | H24: 29885 | I24: 10.75
A25: 1721 | B25: Alstain | C25: Isolde | D25: HR | E25: isoldea | F25: 102 | G25: Building 3 | H25: 33091 | I25: 9.75
A26: 1723 | B26: Sammler | C26: Mark | D26: MK | E26: marks | F26: 145 | G26: Building 1 | H26: 28531 | I26: 13.95
A27: 1758 | B27: Brwyne | C27: Melia | D27: AC | E27: meliab | F27: 107 | G27: Building 2 | H27: 30028 | I27: 11.2
... A38: 1999 | B38: Atherly | C38: Katherine | D38: HR | E38: kathya | F38: 428 | G38: Building 3 | H38: 35981 | I38: 10.15

Sheet XLOOKUP
B2: Emp ID | C2: First Name | D2: Last Name | E2: Dept | F2: Pay Rate | I2: E-mail | J2: Emp ID
B3: 1054 | C3: =_xlfn.XLOOKUP(B3,'Xlookup Emp List'!A2:A38,'Xlookup Emp List'!C2:C38) -> Howard | D3: =_xlfn.XLOOKUP(B3,'Xlookup Emp List'!$A$2:$A$38,'Xlookup Emp List'!$B$2:$B$38,0) -> Smith | E3: =_xlfn.XLOOKUP(B3,'Xlookup Emp List'!$A$2:$A$38,'Xlookup Emp List'!$D$2:$D$38,0) -> AT | I3: howards | J3: =_xlfn.XLOOKUP(I3,'Xlookup Emp List'!$E$2:$E$38,'Xlookup Emp List'!$A$2:$A$38,0) -> 1054
B4: 1056 | C4: =_xlfn.XLOOKUP(B4,'Xlookup Emp List'!A3:A39,'Xlookup Emp List'!C3:C39) -> Joe | D4: =_xlfn.XLOOKUP(B4,'Xlookup Emp List'!$A$2:$A$38,'Xlookup Emp List'!$B$2:$B$38,0) -> Gonzales | E4: =_xlfn.XLOOKUP(B4,'Xlookup Emp List'!$A$2:$A$38,'Xlookup Emp List'!$D$2:$D$38,0) -> AT | I4: joeg | J4: =_xlfn.XLOOKUP(I4,'Xlookup Emp List'!$E$2:$E$38,'Xlookup Emp List'!$A$2:$A$38,0) -> 1056
B5: 1067 | C5: =_xlfn.XLOOKUP(B5,'Xlookup Emp List'!A4:A40,'Xlookup Emp List'!C4:C40) -> Gail | D5: =_xlfn.XLOOKUP(B5,'Xlookup Emp List'!$A$2:$A$38,'Xlookup Emp List'!$B$2:$B$38,0) -> Scote | E5: =_xlfn.XLOOKUP(B5,'Xlookup Emp List'!$A$2:$A$38,'Xlookup Emp List'!$D$2:$D$38,0) -> AT | I5: gails | J5: =_xlfn.XLOOKUP(I5,'Xlookup Emp List'!$E$2:$E$38,'Xlookup Emp List'!$A$2:$A$38,0) -> 1067
B6: 1075 | C6: =_xlfn.XLOOKUP(B6,'Xlookup Emp List'!A5:A41,'Xlookup Emp List'!C5:C41) -> Sheryl | D6: =_xlfn.XLOOKUP(B6,'Xlookup Emp List'!$A$2:$A$38,'Xlookup Emp List'!$B$2:$B$38,0) -> Kane | E6: =_xlfn.XLOOKUP(B6,'Xlookup Emp List'!$A$2:$A$38,'Xlookup Emp List'!$D$2:$D$38,0) -> AD | I6: sherylk | J6: =_xlfn.XLOOKUP(I6,'Xlookup Emp List'!$E$2:$E$38,'Xlookup Emp List'!$A$2:$A$38,0) -> 1075
B7: 1078 | C7: =_xlfn.XLOOKUP(B7,'Xlookup Emp List'!A6:A42,'Xlookup Emp List'!C6:C42) -> Kendrick | D7: =_xlfn.XLOOKUP(B7,'Xlookup Emp List'!$A$2:$A$38,'Xlookup Emp List'!$B$2:$B$38,0) -> Hapsbuch | E7: =_xlfn.XLOOKUP(B7,'Xlookup Emp List'!$A$2:$A$38,'Xlookup Emp List'!$D$2:$D$38,0) -> AC | I7: kendrickh | J7: =_xlfn.XLOOKUP(I7,'Xlookup Emp List'!$E$2:$E$38,'Xlookup Emp List'!$A$2:$A$38,0) -> 1078
B8: 1152 | C8: =_xlfn.XLOOKUP(B8,'Xlookup Emp List'!A7:A43,'Xlookup Emp List'!C7:C43) -> Mark | D8: =_xlfn.XLOOKUP(B8,'Xlookup Emp List'!$A$2:$A$38,'Xlookup Emp List'!$B$2:$B$38,0) -> Henders | E8: =_xlfn.XLOOKUP(B8,'Xlookup Emp List'!$A$2:$A$38,'Xlookup Emp List'!$D$2:$D$38,0) -> AD | I8: markh | J8: =_xlfn.XLOOKUP(I8,'Xlookup Emp List'!$E$2:$E$38,'Xlookup Emp List'!$A$2:$A$38,0) -> 1152
B9: 1196 | C9: =_xlfn.XLOOKUP(B9,'Xlookup Emp List'!A8:A44,'Xlookup Emp List'!C8:C44) -> Katie | D9: =_xlfn.XLOOKUP(B9,'Xlookup Emp List'!$A$2:$A$38,'Xlookup Emp List'!$B$2:$B$38,0) -> Atherton | E9: =_xlfn.XLOOKUP(B9,'Xlookup Emp List'!$A$2:$A$38,'Xlookup Emp List'!$D$2:$D$38,0) -> HR | I9: katiea | J9: =_xlfn.XLOOKUP(I9,'Xlookup Emp List'!$E$2:$E$38,'Xlookup Emp List'!$A$2:$A$38,0) -> 1196
B10: 1284 | C10: =_xlfn.XLOOKUP(B10,'Xlookup Emp List'!A9:A45,'Xlookup Emp List'!C9:C45) -> Frank | D10: =_xlfn.XLOOKUP(B10,'Xlookup Emp List'!$A$2:$A$38,'Xlookup Emp List'!$B$2:$B$38,0) -> Bellwood | E10: =_xlfn.XLOOKUP(B10,'Xlookup Emp List'!$A$2:$A$38,'Xlookup Emp List'!$D$2:$D$38,0) -> MK | I10: frankb | J10: =_xlfn.XLOOKUP(I10,'Xlookup Emp List'!$E$2:$E$38,'Xlookup Emp List'!$A$2:$A$38,0) -> 1284
B11: - | C11: =_xlfn.XLOOKUP(B11,'Xlookup Emp List'!A10:A46,'Xlookup Emp List'!C10:C46) -> #N/A | D11: =_xlfn.XLOOKUP(B11,'Xlookup Emp List'!$A$2:$A$38,'Xlookup Emp List'!$B$2:$B$38,0) -> 0 | E11: =_xlfn.XLOOKUP(B11,'Xlookup Emp List'!$A$2:$A$38,'Xlookup Emp List'!$D$2:$D$38,0) -> 0 | I11: lindac | J11: =_xlfn.XLOOKUP(I11,'Xlookup Emp List'!$E$2:$E$38,'Xlookup Emp List'!$A$2:$A$38,0) -> 1290
B12: - | C12: =_xlfn.XLOOKUP(B12,'Xlookup Emp List'!A11:A47,'Xlookup Emp List'!C11:C47) -> #N/A | D12: =_xlfn.XLOOKUP(B12,'Xlookup Emp List'!$A$2:$A$38,'Xlookup Emp List'!$B$2:$B$38,0) -> 0 | E12: =_xlfn.XLOOKUP(B12,'Xlookup Emp List'!$A$2:$A$38,'Xlookup Emp List'!$D$2:$D$38,0) -> 0 | I12: brentc | J12: =_xlfn.XLOOKUP(I12,'Xlookup Emp List'!$E$2:$E$38,'Xlookup Emp List'!$A$2:$A$38,0) -> 1293
B13: - | C13: =_xlfn.XLOOKUP(B13,'Xlookup Emp List'!A12:A48,'Xlookup Emp List'!C12:C48) -> #N/A | D13: =_xlfn.XLOOKUP(B13,'Xlookup Emp List'!$A$2:$A$38,'Xlookup Emp List'!$B$2:$B$38,0) -> 0 | E13: =_xlfn.XLOOKUP(B13,'Xlookup Emp List'!$A$2:$A$38,'Xlookup Emp List'!$D$2:$D$38,0) -> 0 | I13: sandraes | J13: =_xlfn.XLOOKUP(I13,'Xlookup Emp List'!$E$2:$E$38,'Xlookup Emp List'!$A$2:$A$38,0) -> 1299
B14: 1302 | C14: =_xlfn.XLOOKUP(B14,'Xlookup Emp List'!A13:A49,'Xlookup Emp List'!C13:C49) -> Randy | D14: =_xlfn.XLOOKUP(B14,'Xlookup Emp List'!$A$2:$A$38,'Xlookup Emp List'!$B$2:$B$38,0) -> Sindole | E14: =_xlfn.XLOOKUP(B14,'Xlookup Emp List'!$A$2:$A$38,'Xlookup Emp List'!$D$2:$D$38,0) -> MK | I14: randys | J14: =_xlfn.XLOOKUP(I14,'Xlookup Emp List'!$E$2:$E$38,'Xlookup Emp List'!$A$2:$A$38,0) -> 1302
